Workbook

Sheet Vlookup_1
B3: Final Data | H3: Vendor Data
B4: Fruit Name | C4: Price | D4: Vendor | E4: Purchase Month | H4: Fruit Name | I4: Vendor | J4: Purchase Month
B5: Apple | C5: 7.85 | D5: =VLOOKUP(B5,$H$4:$J$7,2,FALSE) -> Amazon | E5: =VLOOKUP(B5,$H$4:$J$7,3,FALSE) -> Jan | H5: Apple | I5: Amazon | J5: Jan
B6: Orange | C6: 3.25 | D6: =VLOOKUP(B6,$H$4:$J$7,2,FALSE) -> #N/A | E6: =VLOOKUP(B6,$H$4:$J$7,3,FALSE) -> #N/A | H6: Kiwi | I6: BigBasket | J6: Feb
B7: Kiwi | C7: 12.5 | D7: =VLOOKUP(B7,$H$4:$J$7,2,FALSE) -> BigBasket | E7: =VLOOKUP(B7,$H$4:$J$7,3,FALSE) -> Feb | H7: Grapes | I7: Walmart | J7: Mar
B8: Pineapple | C8: 6.35 | D8: =VLOOKUP(B8,$H$4:$J$7,2,FALSE) -> #N/A | E8: =VLOOKUP(B8,$H$4:$J$7,3,FALSE) -> #N/A
B9: Grapes | C9: 2.5 | D9: =VLOOKUP(B9,$H$4:$J$7,2,FALSE) -> Walmart | E9: =VLOOKUP(B9,$H$4:$J$7,3,FALSE) -> Mar
B10: Banana | C10: 6.5 | D10: =VLOOKUP(B10,$H$4:$J$7,2,FALSE) -> #N/A | E10: =VLOOKUP(B10,$H$4:$J$7,3,FALSE) -> #N/A | H10: Collect all the Vendor Information for each fruit in one Table
B11: Apple | C11: 8.75 | D11: =VLOOKUP(B11,$H$4:$J$7,2,FALSE) -> Amazon | E11: =VLOOKUP(B11,$H$4:$J$7,3,FALSE) -> Jan
B12: Pineapple | C12: 4.65 | D12: =VLOOKUP(B12,$H$4:$J$7,2,FALSE) -> #N/A | E12: =VLOOKUP(B12,$H$4:$J$7,3,FALSE) -> #N/A
B13: Apple | C13: 12.85 | D13: =VLOOKUP(B13,$H$4:$J$7,2,FALSE) -> Amazon | E13: =VLOOKUP(B13,$H$4:$J$7,3,FALSE) -> Jan
B14: Orange | C14: 8.25 | D14: =VLOOKUP(B14,$H$4:$J$7,2,FALSE) -> #N/A | E14: =VLOOKUP(B14,$H$4:$J$7,3,FALSE) -> #N/A
B15: Kiwi | C15: 13.5 | D15: =VLOOKUP(B15,$H$4:$J$7,2,FALSE) -> BigBasket | E15: =VLOOKUP(B15,$H$4:$J$7,3,FALSE) -> Feb
B16: Pineapple | C16: 9.95 | D16: =VLOOKUP(B16,$H$4:$J$7,2,FALSE) -> #N/A | E16: =VLOOKUP(B16,$H$4:$J$7,3,FALSE) -> #N/A
B22: Final Data | H22: Vendor Data
B23: Fruit Name | C23: Price | D23: Vendor | E23: Purchase Month | H23: Vendor | I23: Fruit Name | J23: Purchase Month | K23: Vendor
B24: Apple | C24: 7.85 | D24: =VLOOKUP(B24,$I$23:$K$27,3,FALSE) -> Amazon | E24: =VLOOKUP(B24,$I$23:$K$27,2,FALSE) -> Jan | H24: Amazon | I24: Apple | J24: Jan | K24: Amazon
B25: Orange | C25: 3.25 | D25: =VLOOKUP(B25,$I$23:$K$27,3,FALSE) -> BigBasket | E25: =VLOOKUP(B25,$I$23:$K$27,2,FALSE) -> Feb | H25: BigBasket | I25: Orange | J25: Feb | K25: BigBasket
B26: Kiwi | C26: 12.5 | D26: =VLOOKUP(B26,$I$23:$K$27,3,FALSE) -> Kiwi | E26: =VLOOKUP(B26,$I$23:$K$27,2,FALSE) -> Jul | H26: Walmart | I26: Pineapple | J26: Mar | K26: Walmart
B27: Pineapple | C27: 6.35 | D27: =VLOOKUP(B27,$I$23:$K$27,3,FALSE) -> Walmart | E27: =VLOOKUP(B27,$I$23:$K$27,2,FALSE) -> Mar | H27: Kiwi | I27: Kiwi | J27: Jul | K27: Kiwi
B28: Grapes | C28: 2.5 | D28: =VLOOKUP(B28,$I$23:$K$27,3,FALSE) -> #N/A | E28: =VLOOKUP(B28,$I$23:$K$27,2,FALSE) -> #N/A
B29: Banana | C29: 6.5 | D29: =VLOOKUP(B29,$I$23:$K$27,3,FALSE) -> #N/A | E29: =VLOOKUP(B29,$I$23:$K$27,2,FALSE) -> #N/A | H29: Collect all the Purchase Information for each fruit in one Table
B30: Apple | C30: 8.75 | D30: =VLOOKUP(B30,$I$23:$K$27,3,FALSE) -> Amazon | E30: =VLOOKUP(B30,$I$23:$K$27,2,FALSE) -> Jan
B31: Pineapple | C31: 4.65 | D31: =VLOOKUP(B31,$I$23:$K$27,3,FALSE) -> Walmart | E31: =VLOOKUP(B31,$I$23:$K$27,2,FALSE) -> Mar
B32: Apple | C32: 12.85 | D32: =VLOOKUP(B32,$I$23:$K$27,3,FALSE) -> Amazon | E32: =VLOOKUP(B32,$I$23:$K$27,2,FALSE) -> Jan
B33: Orange | C33: 8.25 | D33: =VLOOKUP(B33,$I$23:$K$27,3,FALSE) -> BigBasket | E33: =VLOOKUP(B33,$I$23:$K$27,2,FALSE) -> Feb | I33: It doesn't work right to left.
B34: Kiwi | C34: 13.5 | D34: =VLOOKUP(B34,$I$23:$K$27,3,FALSE) -> Kiwi | E34: =VLOOKUP(B34,$I$23:$K$27,2,FALSE) -> Jul | I34: its work left to right.
B35: Pineapple | C35: 9.95 | D35: =VLOOKUP(B35,$I$23:$K$27,3,FALSE) -> Walmart | E35: =VLOOKUP(B35,$I$23:$K$27,2,FALSE) -> Mar
B40: Final Data | H40: Price Data
B41: Fruit Name | C41: Price | D41: Vendor | E41: Purchase Month | H41: Price | I41: How | J41: Purchase Month
B42: Apple | C42: 7.85 | D42: Amazon | E42: =VLOOKUP(C42,$H$41:$J$47,3,FALSE) -> Jan | H42: 7.85 | I42: Cash | J42: Jan
B43: Orange | C43: 3.25 | D43: BigBasket | E43: =VLOOKUP(C43,$H$41:$J$47,3,FALSE) -> #N/A | H43: 12.5 | I43: Card | J43: Mar
B44: Kiwi | C44: 12.5 | D44: Walmart | E44: =VLOOKUP(C44,$H$41:$J$47,3,FALSE) -> Mar | H44: 6.5 | I44: Card | J44: Mar
B45: Pineapple | C45: 6.35 | D45: Lyft | E45: =VLOOKUP(C45,$H$41:$J$47,3,FALSE) -> #N/A | H45: 8.75 | I45: Cash | J45: Jul
B46: Grapes | C46: 2.5 | D46: DoorDash | E46: =VLOOKUP(C46,$H$41:$J$47,3,FALSE) -> #N/A | H46: 4.65 | I46: Card | J46: Feb
B47: Banana | C47: 6.5 | D47: Google | E47: =VLOOKUP(C47,$H$41:$J$47,3,FALSE) -> Mar | H47: 12.85 | I47: Cash | J47: Mar
B48: Apple | C48: 8.75 | D48: Amazon | E48: =VLOOKUP(C48,$H$41:$J$47,3,FALSE) -> Jul
B49: Pineapple | C49: 4.65 | D49: Lyft | E49: =VLOOKUP(C49,$H$41:$J$47,3,FALSE) -> Feb | H49: Figure out the Purchase month info onto Final Table
B50: Apple | C50: 12.85 | D50: Amazon | E50: =VLOOKUP(C50,$H$41:$J$47,3,FALSE) -> Mar
B51: Orange | C51: 8.25 | D51: BigBasket | E51: =VLOOKUP(C51,$H$41:$J$47,3,FALSE) -> #N/A
...

Sheet Vlookup_2
B4: PersonName | C4: Date of Birth | D4: Pocket Money | H4: Year of Birth | I4: Pocket Money Limit
B5: Mike | C5: 44379 | D5: =VLOOKUP(C5,$H$5:$I$7,2,TRUE) -> 400 | E5: =IFERROR(VLOOKUP(C5,$H$5:$I$7,2,TRUE),150) -> 400 | F5: =VLOOKUP(C5,$H$5:$I$8,2,1) -> 400 | H5: 43466 | I5: 150
B6: Clark | C6: 44001 | D6: =VLOOKUP(C6,$H$5:$I$7,2,TRUE) -> 250 | E6: =IFERROR(VLOOKUP(C6,$H$5:$I$7,2,TRUE),150) -> 250 | F6: =VLOOKUP(C6,$H$5:$I$8,2,1) -> 250 | H6: 43831 | I6: 250
B7: Cornell | C7: 44246 | D7: =VLOOKUP(C7,$H$5:$I$7,2,TRUE) -> 400 | E7: =IFERROR(VLOOKUP(C7,$H$5:$I$7,2,TRUE),150) -> 400 | F7: =VLOOKUP(C7,$H$5:$I$8,2,1) -> 400 | H7: 44197 | I7: 400
B8: Trent | C8: 44377 | D8: =VLOOKUP(C8,$H$5:$I$7,2,TRUE) -> 400 | E8: =IFERROR(VLOOKUP(C8,$H$5:$I$7,2,TRUE),150) -> 400 | F8: =VLOOKUP(C8,$H$5:$I$8,2,1) -> 400
B9: Anderson | C9: 43983 | D9: =VLOOKUP(C9,$H$5:$I$7,2,TRUE) -> 250 | E9: =IFERROR(VLOOKUP(C9,$H$5:$I$7,2,TRUE),150) -> 250 | F9: =VLOOKUP(C9,$H$5:$I$8,2,1) -> 250
B10: Neo | C10: 44220 | D10: =VLOOKUP(C10,$H$5:$I$7,2,TRUE) -> 400 | E10: =IFERROR(VLOOKUP(C10,$H$5:$I$7,2,TRUE),150) -> 400 | F10: =VLOOKUP(C10,$H$5:$I$8,2,1) -> 400 | H10: Find out the Pocket money limit for each person's Date of Birth.
B11: Kylie | C11: 44003 | D11: =VLOOKUP(C11,$H$5:$I$7,2,TRUE) -> 250 | E11: =IFERROR(VLOOKUP(C11,$H$5:$I$7,2,TRUE),150) -> 250 | F11: =VLOOKUP(C11,$H$5:$I$8,2,1) -> 250
B12: Jimmy | C12: 43985 | D12: =VLOOKUP(C12,$H$5:$I$7,2,TRUE) -> 250 | E12: =IFERROR(VLOOKUP(C12,$H$5:$I$7,2,TRUE),150) -> 250 | F12: =VLOOKUP(C12,$H$5:$I$8,2,1) -> 250
B13: Thor | C13: 43495 | D13: =VLOOKUP(C13,$H$5:$I$7,2,TRUE) -> 150 | E13: =IFERROR(VLOOKUP(C13,$H$5:$I$7,2,TRUE),150) -> 150 | F13: =VLOOKUP(C13,$H$5:$I$8,2,1) -> 150
B14: Jane | C14: 44271 | D14: =VLOOKUP(C14,$H$5:$I$7,2,TRUE) -> 400 | E14: =IFERROR(VLOOKUP(C14,$H$5:$I$7,2,TRUE),150) -> 400 | F14: =VLOOKUP(C14,$H$5:$I$8,2,1) -> 400
B15: Zeus | C15: 44730 | D15: =VLOOKUP(C15,$H$5:$I$7,2,TRUE) -> 400 | E15: =IFERROR(VLOOKUP(C15,$H$5:$I$7,2,TRUE),150) -> 400 | F15: =VLOOKUP(C15,$H$5:$I$8,2,1) -> 400
B16: Herald | C16: 43215 | D16: =VLOOKUP(C16,$H$5:$I$7,2,TRUE) -> #N/A | E16: =IFERROR(VLOOKUP(C16,$H$5:$I$7,2,TRUE),150) -> 150 | F16: =VLOOKUP(C16,$H$5:$I$8,2,1) -> #N/A
B20: PersonName | C20: Joining Date | D20: Bonus Amount | H20: PersonName | I20: Date of Joining
B21: Mike | C21: =VLOOKUP(B21,$H$21:$I$26,2,FALSE) -> 44379 | D21: =VLOOKUP(C21,$H$29:$I$33,2,TRUE) -> 100 | H21: Mike | I21: 44379
B22: Clark | C22: =VLOOKUP(B22,$H$21:$I$26,2,FALSE) -> 44001 | D22: =VLOOKUP(C22,$H$29:$I$33,2,TRUE) -> 500 | H22: Clark | I22: 44001
B23: Cornell | C23: =VLOOKUP(B23,$H$21:$I$26,2,FALSE) -> #N/A | D23: =VLOOKUP(C23,$H$29:$I$33,2,TRUE) -> #N/A | H23: Anderson | I23: 43983
B24: Trent | C24: =VLOOKUP(B24,$H$21:$I$26,2,FALSE) -> 44377 | D24: =VLOOKUP(C24,$H$29:$I$33,2,TRUE) -> 100 | H24: Trent | I24: 44377
B25: Anderson | C25: =VLOOKUP(B25,$H$21:$I$26,2,FALSE) -> 43983 | D25: =VLOOKUP(C25,$H$29:$I$33,2,TRUE) -> 500 | H25: Jimmy | I25: 43985
B26: Neo | C26: =VLOOKUP(B26,$H$21:$I$26,2,FALSE) -> #N/A | D26: =VLOOKUP(C26,$H$29:$I$33,2,TRUE) -> #N/A | H26: Zeus | I26: 44730
B27: Kylie | C27: =VLOOKUP(B27,$H$21:$I$26,2,FALSE) -> #N/A | D27: =VLOOKUP(C27,$H$29:$I$33,2,TRUE) -> #N/A
B28: Jimmy | C28: =VLOOKUP(B28,$H$21:$I$26,2,FALSE) -> 43985 | D28: =VLOOKUP(C28,$H$29:$I$33,2,TRUE) -> 500 | H28: Joining Date | I28: Bonus Amount
B29: Thor | C29: =VLOOKUP(B29,$H$21:$I$26,2,FALSE) -> #N/A | D29: =VLOOKUP(C29,$H$29:$I$33,2,TRUE) -> #N/A | H29: 43466 | I29: 1000
B30: Jane | C30: =VLOOKUP(B30,$H$21:$I$26,2,FALSE) -> #N/A | D30: =VLOOKUP(C30,$H$29:$I$33,2,TRUE) -> #N/A | H30: 43831 | I30: 750
B31: Zeus | C31: =VLOOKUP(B31,$H$21:$I$26,2,FALSE) -> 44730 | D31: =VLOOKUP(C31,$H$29:$I$33,2,TRUE) -> 100 | H31: 43983 | I31: 500
B32: Herald | C32: =VLOOKUP(B32,$H$21:$I$26,2,FALSE) -> #N/A | D32: =VLOOKUP(C32,$H$29:$I$33,2,TRUE) -> #N/A | H32: 44197 | I32: 250
H33: 44348 | I33: 100
B38: PersonName | C38: Joining Date | D38: Bonus Amount
B39: Mike | C39: =VLOOKUP(B39,Employee_Data!A1:B13,2,FALSE) -> 44379 | D39: =VLOOKUP(C39,$H$29:$I$33,2,TRUE) -> 100
B40: Clark | C40: =VLOOKUP(B40,Employee_Data!A2:B14,2,FALSE) -> 44001 | D40: =VLOOKUP(C40,$H$29:$I$33,2,TRUE) -> 500
B41: Cornell | C41: =VLOOKUP(B41,Employee_Data!A3:B15,2,FALSE) -> 44246 | D41: =VLOOKUP(C41,$H$29:$I$33,2,TRUE) -> 250
B42: Trent | C42: =VLOOKUP(B42,Employee_Data!A4:B16,2,FALSE) -> 44377 | D42: =VLOOKUP(C42,$H$29:$I$33,2,TRUE) -> 100 | H42: Find out the Pocket money limit for each person's Date of Birth.
B43: Anderson | C43: =VLOOKUP(B43,Employee_Data!A5:B17,2,FALSE) -> 43983 | D43: =VLOOKUP(C43,$H$29:$I$33,2,TRUE) -> 500
B44: Neo | C44: =VLOOKUP(B44,Employee_Data!A6:B18,2,FALSE) -> 44220 | D44: =VLOOKUP(C44,$H$29:$I$33,2,TRUE) -> 250 | H44: Details of Joining Date and Bonus Amount is in "Employee Data" Sheet
B45: Kylie | C45: =VLOOKUP(B45,Employee_Data!A7:B19,2,FALSE) -> 44003 | D45: =VLOOKUP(C45,$H$29:$I$33,2,TRUE) -> 500
B46: Jimmy | C46: =VLOOKUP(B46,Employee_Data!A8:B20,2,FALSE) -> 43985 | D46: =VLOOKUP(C46,$H$29:$I$33,2,TRUE) -> 500
B47: Thor | C47: =VLOOKUP(B47,Employee_Data!A9:B21,2,FALSE) -> 43495 | D47: =VLOOKUP(C47,$H$29:$I$33,2,TRUE) -> 1000
B48: Jane | C48: =VLOOKUP(B48,Employee_Data!A10:B22,2,FALSE) -> 44271 | D48: =VLOOKUP(C48,$H$29:$I$33,2,TRUE) -> 250
B49: Zeus | C49: =VLOOKUP(B49,Employee_Data!A11:B23,2,FALSE) -> 44730 | D49: =VLOOKUP(C49,$H$29:$I$33,2,TRUE) -> 100
B50: Herald | C50: =VLOOKUP(B50,Employee_Data!A12:B24,2,FALSE) -> 43215 | D50: =VLOOKUP(C50,$H$29:$I$33,2,TRUE) -> #N/A

Sheet Employee_Data
A1: PersonName | B1: Joining Date | H1: Joining Date | I1: Bonus Amount
A2: Mike | B2: 44379 | H2: 43466 | I2: 2500
A3: Clark | B3: 44001 | H3: 43831 | I3: 1500
A4: Cornell | B4: 44246 | H4: 43983 | I4: 1000
A5: Trent | B5: 44377 | H5: 44197 | I5: 750
A6: Anderson | B6: 43983 | H6: 44348 | I6: 500
A7: Neo | B7: 44220 | H7: 44348 | I7: 250
A8: Kylie | B8: 44003
A9: Jimmy | B9: 43985
A10: Thor | B10: 43495
A11: Jane | B11: 44271
A12: Zeus | B12: 44730
A13: Herald | B13: 43215

Sheet Vlookup_3
B4: Dress Type | C4: Dress Size | D4: Actual Price | E4: Profit Amount | H4: Dress Size | I4: Profit %
B5: Shirt | C5: S | D5: 787 | E5: =VLOOKUP(C5&"*",$H$5:$I$8,2,FALSE)*D5 -> 98.375 | H5: Small | I5: 0.125
B6: Pants | C6: S | D6: 457 | E6: =VLOOKUP(C6&"*",$H$5:$I$8,2,FALSE)*D6 -> 57.125 | H6: Medium | I6: 0.17
B7: Shirt | C7: M | D7: 411 | E7: =VLOOKUP(C7&"*",$H$5:$I$8,2,FALSE)*D7 -> 69.87 | H7: Large | I7: 0.15
B8: Pants | C8: M | D8: 506 | E8: =VLOOKUP(C8&"*",$H$5:$I$8,2,FALSE)*D8 -> 86.02 | H8: Extra Large | I8: 0.1
B9: Shirt | C9: L | D9: 370 | E9: =VLOOKUP(C9&"*",$H$5:$I$8,2,FALSE)*D9 -> 55.5
B10: Pants | C10: L | D10: 713 | E10: =VLOOKUP(C10&"*",$H$5:$I$8,2,FALSE)*D10 -> 106.95
B11: Shirt | C11: S | D11: 346 | E11: =VLOOKUP(C11&"*",$H$5:$I$8,2,FALSE)*D11 -> 43.25 | H11: Find the Profit Amount for Each Dress Size
B12: Pants | C12: M | D12: 691 | E12: =VLOOKUP(C12&"*",$H$5:$I$8,2,FALSE)*D12 -> 117.47
B13: Pants | C13: L | D13: 461 | E13: =VLOOKUP(C13&"*",$H$5:$I$8,2,FALSE)*D13 -> 69.15
B21: Dress Type | C21: Dress Size | D21: Actual Price | E21: Profit Amount | H21: Margin Remarks | I21: Profit Amount
B22: Shirt | C22: S | D22: 787 | E22: =VLOOKUP(B22&"*",$H$21:$I$23,2,FALSE)*D22 -> 94440 | H22: Shirts have less Margin | I22: 120
B23: Pants | C23: S | D23: 457 | E23: =VLOOKUP(B23&"*",$H$21:$I$23,2,FALSE)*D23 -> 82260 | H23: Pants have higher Margin | I23: 180
B24: Shirt | C24: M | D24: 411 | E24: =VLOOKUP(B24&"*",$H$21:$I$23,2,FALSE)*D24 -> 49320
B25: Pants | C25: M | D25: 506 | E25: =VLOOKUP(B25&"*",$H$21:$I$23,2,FALSE)*D25 -> 91080
B26: Shirt | C26: L | D26: 370 | E26: =VLOOKUP(B26&"*",$H$21:$I$23,2,FALSE)*D26 -> 44400
B27: Pants | C27: L | D27: 713 | E27: =VLOOKUP(B27&"*",$H$21:$I$23,2,FALSE)*D27 -> 128340
B28: Shirt | C28: S | D28: 346 | E28: =VLOOKUP(B28&"*",$H$21:$I$23,2,FALSE)*D28 -> 41520 | H28: Find the Profit Amount for Each Dress Type
B29: Pants | C29: M | D29: 691 | E29: =VLOOKUP(B29&"*",$H$21:$I$23,2,FALSE)*D29 -> 124380
B30: Pants | C30: L | D30: 461 | E30: =VLOOKUP(B30&"*",$H$21:$I$23,2,FALSE)*D30 -> 82980 | H30: Tip: Use Wild Cards

Sheet Vlookup4
B2: Student | C2: Score | D2: Grade | G2: Minimum Marks | H2: Grade
B3: Kom | C3: 56 | D3: =VLOOKUP(C3,$G$2:$H$7,2,TRUE) -> Grade "E" | G3: 35 | H3: Grade "E"
B4: Kyle | C4: 78 | D4: =VLOOKUP(C4,$G$2:$H$7,2,TRUE) -> Grade "C" | G4: 60 | H4: Grade "D"
B5: Samant | C5: 35 | D5: =VLOOKUP(C5,$G$2:$H$7,2,TRUE) -> Grade "E" | G5: 70 | H5: Grade "C"
B6: Tammanah | C6: 12 | D6: =VLOOKUP(C6,$G$2:$H$7,2,TRUE) -> #N/A | G6: 80 | H6: Grade "B"
B7: Muhib | C7: 95 | D7: =VLOOKUP(C7,$G$2:$H$7,2,TRUE) -> Grade "A" | G7: 90 | H7: Grade "A"
B8: Sadhvi | C8: 74 | D8: =VLOOKUP(C8,$G$2:$H$7,2,TRUE) -> Grade "C"
B9: Tom | C9: 66 | D9: =VLOOKUP(C9,$G$2:$H$7,2,TRUE) -> Grade "D"
B10: Karen | C10: 43 | D10: =VLOOKUP(C10,$G$2:$H$7,2,TRUE) -> Grade "E"
B11: Kylie | C11: 67 | D11: =VLOOKUP(C11,$G$2:$H$7,2,TRUE) -> Grade "D"
B12: Eminem | C12: 98 | D12: =VLOOKUP(C12,$G$2:$H$7,2,TRUE) -> Grade "A"
B13: Tamizh | C13: 87 | D13: =VLOOKUP(C13,$G$2:$H$7,2,TRUE) -> Grade "B"
B21: Agent | C21: Jan Sales | D21: Feb Sales | E21: Commision for Jan | F21: Commision for Feb | H21: Sale Value | I21: Commission %
B22: Mike | C22: 8000 | D22: 9500 | E22: =VLOOKUP(C22,$H$21:$I$26,2,TRUE)*C22 -> 560 | F22: =VLOOKUP(D22,$H$21:$I$26,2,TRUE)*D22 -> 665 | H22: 3500 | I22: 0
B23: Clark | C23: 1300 | D23: 3500 | E23: =VLOOKUP(C23,$H$21:$I$26,2,TRUE)*C23 -> #N/A | F23: =VLOOKUP(D23,$H$21:$I$26,2,TRUE)*D23 -> 0 | H23: 5000 | I23: 0.03
B24: Cornell | C24: 13000 | D24: 1839 | E24: =VLOOKUP(C24,$H$21:$I$26,2,TRUE)*C24 -> 1105 | F24: =VLOOKUP(D24,$H$21:$I$26,2,TRUE)*D24 -> #N/A | H24: 8000 | I24: 0.07
B25: Trent | C25: 300 | D25: 35000 | E25: =VLOOKUP(C25,$H$21:$I$26,2,TRUE)*C25 -> #N/A | F25: =VLOOKUP(D25,$H$21:$I$26,2,TRUE)*D25 -> 3500 | H25: 12000 | I25: 0.085
B26: Anderson | C26: 6500 | D26: 8900 | E26: =VLOOKUP(C26,$H$21:$I$26,2,TRUE)*C26 -> 195 | F26: =VLOOKUP(D26,$H$21:$I$26,2,TRUE)*D26 -> 623 | H26: 25000 | I26: 0.1
B27: Neo | C27: 5300 | D27: 7350 | E27: =VLOOKUP(C27,$H$21:$I$26,2,TRUE)*C27 -> 159 | F27: =VLOOKUP(D27,$H$21:$I$26,2,TRUE)*D27 -> 220.5
B28: Kylie | C28: 8950 | D28: 2900 | E28: =VLOOKUP(C28,$H$21:$I$26,2,TRUE)*C28 -> 626.5 | F28: =VLOOKUP(D28,$H$21:$I$26,2,TRUE)*D28 -> #N/A | H28: Create a Commision Amount List with the help of the Slab on the right side
B29: Jimmy | C29: 17600 | D29: 8300 | E29: =VLOOKUP(C29,$H$21:$I$26,2,TRUE)*C29 -> 1496 | F29: =VLOOKUP(D29,$H$21:$I$26,2,TRUE)*D29 -> 581
B30: Thor | C30: 11340 | D30: 4600 | E30: =VLOOKUP(C30,$H$21:$I$26,2,TRUE)*C30 -> 793.8 | F30: =VLOOKUP(D30,$H$21:$I$26,2,TRUE)*D30 -> 0
B31: Jane | C31: 2600 | D31: 3200 | E31: =VLOOKUP(C31,$H$21:$I$26,2,TRUE)*C31 -> #N/A | F31: =VLOOKUP(D31,$H$21:$I$26,2,TRUE)*D31 -> #N/A
B32: Zeus | C32: 4300 | D32: 1700 | E32: =VLOOKUP(C32,$H$21:$I$26,2,TRUE)*C32 -> 0 | F32: =VLOOKUP(D32,$H$21:$I$26,2,TRUE)*D32 -> #N/A
B33: Herald | C33: 7600 | D33: 9200 | E33: =VLOOKUP(C33,$H$21:$I$26,2,TRUE)*C33 -> 228 | F33: =VLOOKUP(D33,$H$21:$I$26,2,TRUE)*D33 -> 644

Sheet Performance data
A1: Employee ID | B1: Employee Name | C1: Region | D1: Product Category | E1: Units Sold | F1: Gross Sales | G1: Refunds | H1: Cost of Goods | I1: Net Sales | J1: Gross Profit | K1: Profit Margin
A2: EMP001 | B2: James Mitchell | C2: North | D2: Accessories | E2: 265 | F2: 4425.56 | G2: 224.43 | H2: 1844.75 | I2: 4201.13 | J2: 2356.38 | K2: 0.561
A3: EMP002 | B3: Maria Martinez | C3: West | D3: Women's Casualwear | E3: 243 | F3: 9955.93 | G3: 711.36 | H3: 4538.65 | I3: 9244.57 | J3: 4705.92 | K3: 0.509
A4: EMP003 | B4: David Collins | C4: East | D4: Men's Casualwear | E4: 311 | F4: 9593.06 | G4: 858.5 | H4: 4143.16 | I4: 8734.56 | J4: 4591.4 | K4: 0.526
A5: EMP004 | B5: Sarah Thompson | C5: South | D5: Footwear | E5: 205 | F5: 12679.28 | G5: 1265.64 | H5: 6290.57 | I5: 11413.64 | J5: 5123.07 | K5: 0.449
A6: EMP005 | B6: Michael Evans | C6: North | D6: Activewear | E6: 122 | F6: 5276.02 | G6: 365.56 | H6: 2165.34 | I6: 4910.46 | J6: 2745.12 | K6: 0.559
A7: EMP006 | B7: Priya White | C7: Central | D7: Accessories | E7: 372 | F7: 4423.68 | G7: 137.69 | H7: 1892.06 | I7: 4285.99 | J7: 2393.93 | K7: 0.558
A8: EMP007 | B8: Wei Roberts | C8: West | D8: Women's Casualwear | E8: 170 | F8: 6011.15 | G8: 352.76 | H8: 2138.64 | I8: 5658.39 | J8: 3519.75 | K8: 0.622
A9: EMP008 | B9: Carlos Carter | C9: East | D9: Men's Casualwear | E9: 165 | F9: 6582.56 | G9: 285.27 | H9: 2806.02 | I9: 6297.29 | J9: 3491.27 | K9: 0.554
A10: EMP009 | B10: Emma Nguyen | C10: South | D10: Kids Wear | E10: 344 | F10: 6509.11 | G10: 350.46 | H10: 2685.47 | I10: 6158.65 | J10: 3473.18 | K10: 0.564
A11: EMP010 | B11: Liam Edwards | C11: Central | D11: Footwear | E11: 144 | F11: 6405.33 | G11: 847.06 | H11: 3198.09 | I11: 5558.27 | J11: 2360.18 | K11: 0.425
A12: EMP011 | B12: Olivia Brown | C12: East | D12: Activewear | E12: 183 | F12: 9705.78 | G12: 630.22 | H12: 3235.07 | I12: 9075.56 | J12: 5840.49 | K12: 0.644
A13: EMP012 | B13: Noah Clark | C13: West | D13: Accessories | E13: 358 | F13: 7912.32 | G13: 179.59 | H13: 2469.45 | I13: 7732.73 | J13: 5263.28 | K13: 0.681
... A51: EMP050 | B51: Sara Khan | C51: West | D51: Accessories | E51: 285 | F51: 6120.5 | G51: 210.15 | H51: 1985.6 | I51: 5910.35 | J51: 3924.75 | K51: 0.664

Sheet Index and Match
A1: Employee Lookup — built with INDEX + MATCH
A2: Type an Employee ID into the yellow cell to pull their stats from 'Performance Data'.
A4: Enter Employee ID: | B4: EMP001 | F4: Search value | G4: Row value | H4: Column value
F5: =INDEX('Performance data'!A1:K51,15,2) -> Ethan Miller | G5: =MATCH("Ethan Miller",'Performance data'!B1:B51,0) -> 15 | H5: =MATCH(F5,'Performance data'!A15:K15,0) -> 2
A6: Employee Name | B6: {=INDEX('Performance data'!$B$1:$B$51,MATCH($B$4,'Performance data'!$A$1:$A$51,0))} -> James Mitchell
A7: Region | B7: {=INDEX('Performance data'!$C$1:$C$51,MATCH($B$4,'Performance data'!$A$1:$A$51,0))} -> North
A8: Product Category | B8: {=INDEX('Performance data'!$D$1:$D$51,MATCH($B$4,'Performance data'!$A$1:$A$51,0))} -> Accessories
A9: Units Sold | B9: {=INDEX('Performance data'!$E$1:$E$51,MATCH($B$4,'Performance data'!$A$1:$A$51,0))} -> 265
A10: Gross Sales ($) | B10: {=INDEX('Performance data'!$F$1:$F$51,MATCH($B$4,'Performance data'!$A$1:$A$51,0))} -> 4425.56
A11: Refunds ($) | B11: {=INDEX('Performance data'!$G$1:$G$51,MATCH($B$4,'Performance data'!$A$1:$A$51,0))} -> 224.43
A12: Net Sales ($) | B12: {=INDEX('Performance data'!$I$1:$I$51,MATCH($B$4,'Performance data'!$A$1:$A$51,0))} -> 4201.13
A13: Profit Margin (%) | B13: {=INDEX('Performance data'!$K$1:$K$51,MATCH($B$4,'Performance data'!$A$1:$A$51,0))} -> 0.561
A15: Bonus — pick any field by name (INDEX/MATCH across rows AND columns):
A16: Pick a field name: | B16: Net Sales
A17: Result: | B17: {=INDEX('Performance data'!$A$1:$K$51,MATCH($B$4,'Performance data'!$A$1:$A$51,0),MATCH($B$16,'Performance data'!$A$1:$K$1,0))} -> 4201.13
A19: Top performer by Net Sales: | B19: Nathan Wright

Sheet XLOOKUP
E1: Purchase Data
B2: S.No | C2: fruits | D2: Store Purchased | E2: Amount | F2: No of Days in Transit | G2: Profit % | I2: Merchant | J2: Profit % | L2: Merchant | M2: No of Days in Transit
B3: 1 | C3: apple | D3: Amazon | E3: 311 | F3: =_xlfn.XLOOKUP(D3,$L$2:$L$8,$M$2:$M$8) -> 7 | G3: =_xlfn.XLOOKUP(D3,$I$2:$I$8,$J$2:$J$8) -> 0.2 | I3: Amazon | J3: 0.2 | L3: Amazon | M3: 7
B4: 2 | C4: orange | D4: Walmart | E4: 543 | F4: =_xlfn.XLOOKUP(D4,$L$2:$L$8,$M$2:$M$8) -> 6 | G4: =_xlfn.XLOOKUP(D4,$I$2:$I$8,$J$2:$J$8) -> 0.18 | I4: Walmart | J4: 0.18 | L4: Walmart | M4: 6
B5: 3 | C5: kiwifruit | D5: Digifresh | E5: 338 | F5: =_xlfn.XLOOKUP(D5,$L$2:$L$8,$M$2:$M$8) -> 7 | G5: =_xlfn.XLOOKUP(D5,$I$2:$I$8,$J$2:$J$8) -> 0.23 | I5: Digifresh | J5: 0.23 | L5: Digifresh | M5: 7
B6: 4 | C6: pineapple | D6: BigBasket | E6: 308 | F6: =_xlfn.XLOOKUP(D6,$L$2:$L$8,$M$2:$M$8) -> 3 | G6: =_xlfn.XLOOKUP(D6,$I$2:$I$8,$J$2:$J$8) -> 0.07 | I6: BigBasket | J6: 0.07 | L6: BigBasket | M6: 3
B7: 5 | C7: pomogranet | D7: Farmer | E7: 499 | F7: =_xlfn.XLOOKUP(D7,$L$2:$L$8,$M$2:$M$8) -> 1 | G7: =_xlfn.XLOOKUP(D7,$I$2:$I$8,$J$2:$J$8) -> 0.05 | I7: Farmer | J7: 0.05 | L7: Farmer | M7: 1
B8: 6 | C8: grape | D8: Fruit Wholeseller | E8: 366 | F8: =_xlfn.XLOOKUP(D8,$L$2:$L$8,$M$2:$M$8) -> 5 | G8: =_xlfn.XLOOKUP(D8,$I$2:$I$8,$J$2:$J$8) -> 0.4 | I8: Fruit Wholeseller | J8: 0.4 | L8: Fruit Wholeseller | M8: 5
B9: 7 | C9: banana | D9: Amazon | E9: 452 | F9: =_xlfn.XLOOKUP(D9,$L$2:$L$8,$M$2:$M$8) -> 7 | G9: =_xlfn.XLOOKUP(D9,$I$2:$I$8,$J$2:$J$8) -> 0.2
B10: 8 | C10: Pear | D10: Walmart | E10: 369 | F10: =_xlfn.XLOOKUP(D10,$L$2:$L$8,$M$2:$M$8) -> 6 | G10: =_xlfn.XLOOKUP(D10,$I$2:$I$8,$J$2:$J$8) -> 0.18
B11: 9 | C11: Mango | D11: BigBasket | E11: 332 | F11: =_xlfn.XLOOKUP(D11,$L$2:$L$8,$M$2:$M$8) -> 3 | G11: =_xlfn.XLOOKUP(D11,$I$2:$I$8,$J$2:$J$8) -> 0.07
B12: 10 | C12: watermelon | D12: Digifresh | E12: 485 | F12: =_xlfn.XLOOKUP(D12,$L$2:$L$8,$M$2:$M$8) -> 7 | G12: =_xlfn.XLOOKUP(D12,$I$2:$I$8,$J$2:$J$8) -> 0.23
A15: Find the "Days in Transit" from "1-9" Dataset using "Margin%"(0nly values that are higher to the current value)
B17: S.No | C17: fruits | D17: Store Purchased | E17: Margin % | F17: No of Days in Transit | J17: Profit % | K17: Merchant | L17: No of Days in Transit
B18: 1 | C18: apple | D18: Amazon | E18: 0.19 | F18: =_xlfn.XLOOKUP(E18,$J$18:$J$23,$L$18:$L$23,"NOT Found",1) -> 7 | J18: 0.2 | K18: Amazon | L18: 7
B19: 2 | C19: orange | D19: Walmart | E19: 0.18 | F19: =_xlfn.XLOOKUP(E19,$J$18:$J$23,$L$18:$L$23,"NOT Found",1) -> 6 | J19: 0.18 | K19: Walmart | L19: 6
B20: 3 | C20: kiwifruit | D20: Digifresh | E20: 0.21 | F20: =_xlfn.XLOOKUP(E20,$J$18:$J$23,$L$18:$L$23,"NOT Found",1) -> 7 | J20: 0.23 | K20: Digifresh | L20: 7
B21: 4 | C21: pineapple | D21: BigBasket | E21: 0.24 | F21: =_xlfn.XLOOKUP(E21,$J$18:$J$23,$L$18:$L$23,"NOT Found",1) -> 5 | J21: 0.07 | K21: BigBasket | L21: 3
B22: 5 | C22: pomogranete | D22: Farmer | E22: 0.08 | F22: =_xlfn.XLOOKUP(E22,$J$18:$J$23,$L$18:$L$23,"NOT Found",1) -> 6 | J22: 0.05 | K22: Farmer | L22: 1
B23: 6 | C23: grape | D23: Fruit Wholeseller | E23: 0.09 | F23: =_xlfn.XLOOKUP(E23,$J$18:$J$23,$L$18:$L$23,"NOT Found",1) -> 6 | J23: 0.4 | K23: Fruit Wholeseller | L23: 5
B24: 7 | C24: banana | D24: Amazon | E24: 0.05 | F24: =_xlfn.XLOOKUP(E24,$J$18:$J$23,$L$18:$L$23,"NOT Found",1) -> 1
B25: 8 | C25: Pear | D25: Walmart | E25: 0.01 | F25: =_xlfn.XLOOKUP(E25,$J$18:$J$23,$L$18:$L$23,"NOT Found",1) -> 1
B26: 9 | C26: Mango | D26: BigBasket | E26: 0.46 | F26: =_xlfn.XLOOKUP(E26,$J$18:$J$23,$L$18:$L$23,"NOT Found",1) -> NOT Found
B27: 10 | C27: watermelon | D27: Digifresh | E27: 0.37 | F27: =_xlfn.XLOOKUP(E27,$J$18:$J$23,$L$18:$L$23,"NOT Found",1) -> 5
A30: Find the "Days in Transit" from "1-9" Dataset using "Margin%"(0nly values that are lower to the current value)
B32: S.No | C32: fruits | D32: Store Purchased | E32: Margin % | F32: No of Days in Transit | J32: Profit % | K32: Merchant | L32: No of Days in Transit
B33: 1 | C33: apple | D33: Amazon | E33: 0.19 | F33: =_xlfn.XLOOKUP(E34,$J$33:$J$39,$L$33:$L$39,"Not Found",-1) -> 6 | J33: 0.2 | K33: Amazon | L33: 7
B34: 2 | C34: orange | D34: Walmart | E34: 0.18 | F34: =_xlfn.XLOOKUP(E35,$J$34:$J$39,$L$34:$L$39,"Not Found",-1) -> 6 | J34: 0.18 | K34: Walmart | L34: 6
B35: 3 | C35: kiwifruit | D35: Digifresh | E35: 0.21 | F35: =_xlfn.XLOOKUP(E36,$J$34:$J$39,$L$34:$L$39,"Not Found",-1) -> 7 | J35: 0.23 | K35: Digifresh | L35: 7
B36: 4 | C36: pineapple | D36: BigBasket | E36: 0.24 | F36: =_xlfn.XLOOKUP(E37,$J$34:$J$39,$L$34:$L$39,"Not Found",-1) -> 3 | J36: 0.07 | K36: BigBasket | L36: 3
B37: 5 | C37: pomogranete | D37: Farmer | E37: 0.08 | F37: =_xlfn.XLOOKUP(E38,$J$34:$J$39,$L$34:$L$39,"Not Found",-1) -> 3 | J37: 0.05 | K37: Farmer | L37: 1
B38: 6 | C38: grape | D38: Fruit Wholeseller | E38: 0.09 | F38: =_xlfn.XLOOKUP(E39,$J$34:$J$39,$L$34:$L$39,"Not Found",-1) -> 1 | J38: 0.4 | K38: Fruit Wholeseller | L38: 5
B39: 7 | C39: banana | D39: Amazon | E39: 0.05 | F39: =_xlfn.XLOOKUP(E40,$J$34:$J$39,$L$34:$L$39,"Not Found",-1) -> Not Found
B40: 8 | C40: Pear | D40: Walmart | E40: 0.01 | F40: =_xlfn.XLOOKUP(E41,$J$34:$J$39,$L$34:$L$39,"Not Found",-1) -> 5
B41: 9 | C41: Mango | D41: BigBasket | E41: 0.46 | F41: =_xlfn.XLOOKUP(E42,$J$34:$J$39,$L$34:$L$39,"Not Found",-1) -> 7
B42: 10 | C42: watermelon | D42: Digifresh | E42: 0.37 | F42: =_xlfn.XLOOKUP(E43,$J$34:$J$39,$L$34:$L$39,"Not Found",-1) -> 0
B45: Find the "Days in Transit" from "I-73" Dataset using "Merchant Name")
B47: S.No | C47: fruits | D47: Store Purchased | E47: Margin % | F47: No of Days in Transit | I47: Profit % | J47: Merchant | K47: No of Days in Transit
B48: 1 | C48: apple | D48: Amazo | E48: 0.19 | F48: =_xlfn.XLOOKUP(D48&"*",$J$48:$J$53,$K$48:$K$53,"Not Found",2) -> 7 | I48: 0.2 | J48: Amazon | K48: 7
B49: 2 | C49: orange | D49: Walma | E49: 0.18 | F49: =_xlfn.XLOOKUP(D49&"*",$J$48:$J$53,$K$48:$K$53,"Not Found",2) -> 6 | I49: 0.18 | J49: Walmart | K49: 6
...
